<?xml version="1.0" encoding="UTF-8"?>
<!-- Generated by org.testng.reporters.JUnitReportReporter -->
<testsuite hostname="ALIPL5413" failures="1" tests="2" name="SauceDemo_Tests.Invalid_credentials" time="0.209" errors="0" timestamp="2023-06-28T17:35:37 IST" skipped="0">
  <testcase classname="SauceDemo_Tests.Invalid_credentials" name="error" time="0.027">
    <failure message="expected [epic sadface: Username and password do not match any user in this service] but found [Epic sadface: Username and password do not match any user in this service]" type="java.lang.AssertionError">
      <![CDATA[java.lang.AssertionError: expected [epic sadface: Username and password do not match any user in this service] but found [Epic sadface: Username and password do not match any user in this service]
at org.testng.Assert.fail(Assert.java:110)
at org.testng.Assert.failNotEquals(Assert.java:1577)
at org.testng.Assert.assertEqualsImpl(Assert.java:149)
at org.testng.Assert.assertEquals(Assert.java:131)
at org.testng.Assert.assertEquals(Assert.java:655)
at org.testng.Assert.assertEquals(Assert.java:665)
at SauceDemo_Tests.Invalid_credentials.error(Invalid_credentials.java:60)
at java.base/jdk.internal.reflect.NativeMethodAccessorImpl.invoke0(Native Method)
at java.base/jdk.internal.reflect.NativeMethodAccessorImpl.invoke(NativeMethodAccessorImpl.java:77)
at java.base/jdk.internal.reflect.DelegatingMethodAccessorImpl.invoke(DelegatingMethodAccessorImpl.java:43)
at java.base/java.lang.reflect.Method.invoke(Method.java:568)
at org.testng.internal.invokers.MethodInvocationHelper.invokeMethod(MethodInvocationHelper.java:139)
at org.testng.internal.invokers.MethodInvocationHelper.invokeMethodConsideringTimeout(MethodInvocationHelper.java:69)
at org.testng.internal.invokers.ConfigInvoker.invokeConfigurationMethod(ConfigInvoker.java:361)
at org.testng.internal.invokers.ConfigInvoker.invokeConfigurations(ConfigInvoker.java:296)
at org.testng.TestRunner.invokeTestConfigurations(TestRunner.java:644)
at org.testng.TestRunner.afterRun(TestRunner.java:914)
at org.testng.TestRunner.run(TestRunner.java:605)
at org.testng.SuiteRunner.runTest(SuiteRunner.java:437)
at org.testng.SuiteRunner.runSequentially(SuiteRunner.java:431)
at org.testng.SuiteRunner.privateRun(SuiteRunner.java:391)
at org.testng.SuiteRunner.run(SuiteRunner.java:330)
at org.testng.SuiteRunnerWorker.runSuite(SuiteRunnerWorker.java:52)
at org.testng.SuiteRunnerWorker.run(SuiteRunnerWorker.java:95)
at org.testng.TestNG.runSuitesSequentially(TestNG.java:1256)
at org.testng.TestNG.runSuitesLocally(TestNG.java:1176)
at org.testng.TestNG.runSuites(TestNG.java:1099)
at org.testng.TestNG.run(TestNG.java:1067)
at org.testng.remote.AbstractRemoteTestNG.run(AbstractRemoteTestNG.java:115)
at org.testng.remote.RemoteTestNG.initAndRun(RemoteTestNG.java:251)
at org.testng.remote.RemoteTestNG.main(RemoteTestNG.java:77)
]]>
    </failure>
  </testcase> <!-- error -->
  <system-out/>
  <testcase classname="SauceDemo_Tests.Invalid_credentials" name="log_in" time="0.182"/>
  <system-out/>
</testsuite> <!-- SauceDemo_Tests.Invalid_credentials -->
